<?xml version="1.0"?>
<robot name="cute_bot">
  <!-- Materials -->
  <material name="blue">
    <color rgba="0 0 1 1"/>
  </material>
  <material name="pink">
    <color rgba="1 0.75 0.8 1"/>
  </material>
  <material name="black">
    <color rgba="0 0 0 1"/>
  </material>

  <!-- Base link -->
  <link name="base_link">
    <visual>
      <geometry>
        <box size="0.3 0.2 0.1"/>
      </geometry>
      <material name="blue"/>
    </visual>
    <collision>
      <geometry>
        <box size="0.3 0.2 0.1"/>
      </geometry>
    </collision>
    <inertial>
      <mass value="1.0"/>
      <inertia ixx="0.01" ixy="0.0" ixz="0.0" iyy="0.01" iyz="0.0" izz="0.01"/>
    </inertial>
  </link>

  <!-- Head link -->
  <joint name="head_joint" type="fixed">
    <parent link="base_link"/>
    <child link="head_link"/>
    <origin xyz="0 0 0.15" rpy="0 0 0"/>
  </joint>
  <link name="head_link">
    <visual>
      <geometry>
        <sphere radius="0.05"/>
      </geometry>
      <material name="pink"/>
    </visual>
    <collision>
      <geometry>
        <sphere radius="0.05"/>
      </geometry>
    </collision>
    <inertial>
      <mass value="0.2"/>
      <inertia ixx="0.001" ixy="0.0" ixz="0.0" iyy="0.001" iyz="0.0" izz="0.001"/>
    </inertial>
  </link>

  <!-- Left wheel -->
  <joint name="wheel_left_joint" type="continuous">
    <parent link="base_link"/>
    <child link="wheel_left_link"/>
    <origin xyz="0.1 0.11 -0.05" rpy="0 0 0"/>
    <axis xyz="0 1 0"/>
  </joint>
  <link name="wheel_left_link">
    <visual>
      <geometry>
        <cylinder radius="0.03" length="0.02"/>
      </geometry>
      <material name="black"/>
    </visual>
    <collision>
      <geometry>
        <cylinder radius="0.03" length="0.02"/>
      </geometry>
    </collision>
    <inertial>
      <mass value="0.1"/>
      <inertia ixx="0.0001" ixy="0.0" ixz="0.0" iyy="0.0001" iyz="0.0" izz="0.0001"/>
    </inertial>
  </link>

  <!-- Right wheel -->
  <joint name="wheel_right_joint" type="continuous">
    <parent link="base_link"/>
    <child link="wheel_right_link"/>
    <origin xyz="0.1 -0.11 -0.05" rpy="0 0 0"/>
    <axis xyz="0 1 0"/>
  </joint>
  <link name="wheel_right_link">
    <visual>
      <geometry>
        <cylinder radius="0.03" length="0.02"/>
      </geometry>
      <material name="black"/>
    </visual>
    <collision>
      <geometry>
        <cylinder radius="0.03" length="0.02"/>
      </geometry>
    </collision>
    <inertial>
      <mass value="0.1"/>
      <inertia ixx="0.0001" ixy="0.0" ixz="0.0" iyy="0.0001" iyz="0.0" izz="0.0001"/>
    </inertial>
  </link>
</robot>